<?xml version="1.0" ?>
<!-- =================================================================================== -->
<!-- |    This document was autogenerated by xacro from src/walker_arm/hiwin_description/urdf/ra.urdf.xacro | -->
<!-- |    EDITING THIS FILE BY HAND IS NOT RECOMMENDED                                 | -->
<!-- =================================================================================== -->
<robot name="hiwin">
  <!-- create link fixed to the "world" -->
  <link name="world"/>
  <!-- ========== 組件加載器 ========== -->
  <!-- 功能：集中管理平台（platform）和末端執行器（ee）的選擇邏輯 -->
  <!-- 職責：根據參數值判斷並調用對應的巨集 -->
  <!-- 無平台配置 -->
  <!-- AGV 平台配置 -->
  <!-- 包含安全地板和 AGV 平台的完整定義 -->
  <!-- HIWIN 平台配置 -->
  <!-- 參考 agv_platform.xacro 建立；請依需求調整網格檔路徑與位姿參數 -->
  <!-- 無末端執行器配置 -->
  <!-- 提供最小化的 TCP (tool0)，確保 SRDF 中 tip_link=tool0 保持有效 -->
  <!-- 空巨集：不添加任何平台相關的連結或關節 -->
  <!-- 機械手臂將直接連接到世界座標系 -->
  <!-- 新增平台時只需在這裡新增 if 判斷 -->
  <!-- 例如：
    <xacro:if value="${platform_type == 'mobile_base'}">
      <xacro:mobile_base_platform tf_prefix="${tf_prefix}"/>
    </xacro:if>
    -->
  <link name="base_link">
    <visual>
      <origin rpy="0 0 0" xyz="0 0 0"/>
      <geometry>
        <mesh filename="../meshes/ra605_710/visual/base.stl" scale="1 1 1"/>
      </geometry>
      <material name="LightGrey">
        <color rgba="0.7 0.7 0.7 1.0"/>
      </material>
    </visual>
    <collision>
      <origin rpy="0 0 0" xyz="0 0 0"/>
      <geometry>
        <mesh filename="../meshes/ra605_710/collision/base.stl" scale="1 1 1"/>
      </geometry>
    </collision>
  </link>
  <link name="link_1">
    <visual>
      <origin rpy="0 0 0" xyz="0 0 0"/>
      <geometry>
        <mesh filename="../meshes/ra605_710/visual/link_1.stl" scale="1 1 1"/>
      </geometry>
      <material name="LightGrey">
        <color rgba="0.7 0.7 0.7 1.0"/>
      </material>
    </visual>
    <collision>
      <origin rpy="0 0 0" xyz="0 0 0"/>
      <geometry>
        <mesh filename="../meshes/ra605_710/collision/link_1.stl" scale="1 1 1"/>
      </geometry>
    </collision>
  </link>
  <link name="link_2">
    <visual>
      <origin rpy="0 0 0" xyz="0 0 0"/>
      <geometry>
        <mesh filename="../meshes/ra605_710/visual/link_2.stl" scale="1 1 1"/>
      </geometry>
      <material name="LightGrey">
        <color rgba="0.7 0.7 0.7 1.0"/>
      </material>
    </visual>
    <collision>
      <origin rpy="0 0 0" xyz="0 0 0"/>
      <geometry>
        <mesh filename="../meshes/ra605_710/collision/link_2.stl" scale="1 1 1"/>
      </geometry>
    </collision>
  </link>
  <link name="link_3">
    <visual>
      <origin rpy="0 0 0" xyz="0 0 0"/>
      <geometry>
        <mesh filename="../meshes/ra605_710/visual/link_3.stl" scale="1 1 1"/>
      </geometry>
      <material name="LightGrey">
        <color rgba="0.7 0.7 0.7 1.0"/>
      </material>
    </visual>
    <collision>
      <origin rpy="0 0 0" xyz="0 0 0"/>
      <geometry>
        <mesh filename="../meshes/ra605_710/collision/link_3.stl" scale="1 1 1"/>
      </geometry>
    </collision>
  </link>
  <link name="link_4">
    <visual>
      <origin rpy="0 0 0" xyz="0 0 0"/>
      <geometry>
        <mesh filename="../meshes/ra605_710/visual/link_4.stl" scale="1 1 1"/>
      </geometry>
      <material name="LightGrey">
        <color rgba="0.7 0.7 0.7 1.0"/>
      </material>
    </visual>
    <collision>
      <origin rpy="0 0 0" xyz="0 0 0"/>
      <geometry>
        <mesh filename="../meshes/ra605_710/collision/link_4.stl" scale="1 1 1"/>
      </geometry>
    </collision>
  </link>
  <link name="link_5">
    <visual>
      <origin rpy="0 0 0" xyz="0 0 0"/>
      <geometry>
        <mesh filename="../meshes/ra605_710/visual/link_5.stl" scale="1 1 1"/>
      </geometry>
      <material name="LightGrey">
        <color rgba="0.7 0.7 0.7 1.0"/>
      </material>
    </visual>
    <collision>
      <origin rpy="0 0 0" xyz="0 0 0"/>
      <geometry>
        <mesh filename="../meshes/ra605_710/collision/link_5.stl" scale="1 1 1"/>
      </geometry>
    </collision>
  </link>
  <link name="link_6">
    <visual>
      <origin rpy="0 0 0" xyz="0 0 0"/>
      <geometry>
        <mesh filename="../meshes/ra605_710/visual/link_6.stl" scale="1 1 1"/>
      </geometry>
      <material name="LightGrey">
        <color rgba="0.7 0.7 0.7 1.0"/>
      </material>
    </visual>
    <collision>
      <origin rpy="0 0 0" xyz="0 0 0"/>
      <geometry>
        <mesh filename="../meshes/ra605_710/collision/link_6.stl" scale="1 1 1"/>
      </geometry>
    </collision>
  </link>
  <!-- base_joint fixes base_link to the environment -->
  <joint name="base_joint" type="fixed">
    <origin rpy="0 0 0" xyz="0 0 0"/>
    <parent link="world"/>
    <child link="base_link"/>
  </joint>
  <!-- joints - main serial chain -->
  <joint name="joint_1" type="revolute">
    <origin rpy="0 0 0" xyz="0 0 0.375"/>
    <parent link="base_link"/>
    <child link="link_1"/>
    <axis xyz="0 0 1"/>
    <limit effort="101.6" lower="-2.8797932657906435" upper="2.8797932657906435" velocity="3.9269908169872414"/>
  </joint>
  <joint name="joint_2" type="revolute">
    <origin rpy="0 0 0" xyz="0 0.03 0"/>
    <parent link="link_1"/>
    <child link="link_2"/>
    <axis xyz="1 0 0"/>
    <limit effort="127" lower="-2.181661564992912" upper="1.4835298641951802" velocity="3.141592653589793"/>
  </joint>
  <joint name="joint_3" type="revolute">
    <origin rpy="0 0 0" xyz="0 0 0.34"/>
    <parent link="link_2"/>
    <child link="link_3"/>
    <axis xyz="1 0 0"/>
    <limit effort="50.96" lower="-0.9599310885968813" upper="3.2288591161895095" velocity="3.9269908169872414"/>
  </joint>
  <joint name="joint_4" type="revolute">
    <origin rpy="0 0 0" xyz="0 0 0.04"/>
    <parent link="link_3"/>
    <child link="link_4"/>
    <axis xyz="0 1 0"/>
    <limit effort="34.344" lower="-3.3161255787892263" upper="3.3161255787892263" velocity="2.907718533822553"/>
  </joint>
  <joint name="joint_5" type="revolute">
    <origin rpy="0 0 0" xyz="0 0.338 0"/>
    <parent link="link_4"/>
    <child link="link_5"/>
    <axis xyz="1 0 0"/>
    <limit effort="12.72" lower="-2.007128639793479" upper="2.007128639793479" velocity="3.9269908169872414"/>
  </joint>
  <joint name="joint_6" type="revolute">
    <origin rpy="0 0 0" xyz="0 0.0865 0"/>
    <parent link="link_5"/>
    <child link="link_6"/>
    <axis xyz="0 1 0"/>
    <limit effort="7.95" lower="-6.283185307179586" upper="6.283185307179586" velocity="6.283185307179586"/>
  </joint>
  <!-- ROS-Industrial 'flange' frame - attachment point for EEF models -->
  <link name="flange"/>
  <joint name="flange" type="fixed">
    <parent link="link_6"/>
    <child link="flange"/>
    <origin rpy="-1.5708 0 0" xyz="0 0 0"/>
  </joint>
  <!-- 新增平台時只需在這裡新增 if 判斷 -->
  <!-- 例如：
    <xacro:if value="${platform_type == 'mobile_base'}">
      <xacro:hiwin_arm ... parent="mobile_base" .../>
    </xacro:if>
    -->
  <!-- 用紅色球體表示工具座標系原點 -->
  <!-- 紅色用於標示無末端執行器的 TCP -->
  <link name="tool0">
    <visual>
      <origin rpy="0 0 0" xyz="0 0 0"/>
      <geometry>
        <sphere radius="0.005"/>
      </geometry>
      <material name="Red">
        <color rgba="1 0 0 1"/>
      </material>
    </visual>
  </link>
  <!-- 將 tool0 固定連接到法蘭盤 -->
  <joint name="flange-tool0" type="fixed">
    <parent link="flange"/>
    <child link="tool0"/>
    <origin rpy="0 0 0" xyz="0 0 0"/>
  </joint>
  <!-- 新增末端執行器時只需在這裡新增 if 判斷 -->
  <!-- 例如：
    <xacro:if value="${ee_type == 'suction_cup'}">
      <xacro:suction_cup_gripper tf_prefix="${tf_prefix}"/>
    </xacro:if>
    -->
</robot>
